Workbook

Sheet 2025년 1분기
B1: 1분기(목표) | C1: 세부 계획 | D1: 수치화 | E1: 1년 목표 | F1: 5년 목표 | G1: 10년 목표 | H1: 목표 | I1: 실적 | J1: 달성률 | K1: 1 | L1: 2 | M1: 3 | N1: 4 | O1: 5 | P1: 6 | Q1: 7 | R1: 8 | S1: 9 | T1: 10 | U1: 11 | V1: 12 | W1: 13 | X1: 14 | Y1: 15 | Z1: 16 | AA1: 17 | AB1: 18 | AC1: 19 | AD1: 20 | AE1: 21 | AF1: 22 | AG1: 23 | AH1: 24 | AI1: 25 | AJ1: 26 | AK1: 27 | AL1: 28 | AM1: 29 | AN1: 30 | AO1: 31
A2: N잡 | B2: 1. 월 매출 500 달성 | C2: - 매일 소싱할 곳 찾기 | D2: 주 5회 | H2: 3 | I2: =countif(K2:AO2,"O") -> 2 | J2: =I2/H2 -> 0.66666667 | K2: O | L2: O
C3: - 주 1회 구매 시도 | D3: 주 1회
C4: - 구입시 기록 및 수익률 체크 | D4: 월 1회
B5: 2, 자동화 프로그램 만들기 | C5: - 프로그래밍 책 보고 개발하기 | D5: 주 2회
C6: - 최종 프로그램 | D6: 1분기
B7: 3. 미캔 요소 1000개 올리기 | C7: - 최소한으로 자동화(+프로그램) 시켜서 주 100개 | D7: 주 1회
A8: 재테크 공부 | B8: 1. 독서 3권 , 양보다 질로 무조건 행동하기 | C8: - 한달에 한권, 무조건 행동할꺼 하나 뽑아내서 실행하기 | D8: 주 1회
B9: 2. 부동산, 주식 신문 읽기 | C9: - 신문 or 유튜브 or 블로거 보고 매일 간단하게라도 정리하기 | D9: 주 5회
C10: - 경제 지표 구글 스프레드에 작성 | D10: 주 5회
B11: 3. 직원 관리 | C11: - 해당 지역 분석 하기 | D11: 주 1회
C12: - 역전세 대비, 공급 파악하기 | D12: 월 2회
A14: 건강 | B14: 1. 운동하기 | C14: - 달리기 or 헬스 | D14: 주 4회
C15: - 인바디 체크 (근육량 34kg, 체지방 12%) | D15: 월 1회
C16: - 운동 기록하기( 주별 무게 및 횟수 체크) | D16: 주 4회
B17: 2. 비타민 챙겨먹기 | C17: - 비타민 책 읽고 정리 후 먹기 | D17: 일 1회

Sheet 2025년 1분기(수정)
B1: 1분기(목표) | C1: 세부 계획 | D1: 수치화 | E1: 1월 실적 | F1: 피드백 | G1: 2월 계획 | H1: 1년 목표 | I1: 5년 목표 | J1: 10년 목표 | K1: 목표 | L1: 실적 | M1: 달성률 | N1: 1 | O1: 2 | P1: 3 | Q1: 4 | R1: 5 | S1: 6 | T1: 7 | U1: 8 | V1: 9 | W1: 10 | X1: 11 | Y1: 12 | Z1: 13 | AA1: 14 | AB1: 15 | AC1: 16 | AD1: 17 | AE1: 18 | AF1: 19 | AG1: 20 | AH1: 21 | AI1: 22 | AJ1: 23 | AK1: 24 | AL1: 25 | AM1: 26 | AN1: 27 | AO1: 28 | AP1: 29 | AQ1: 30 | AR1: 31
A2: N잡 | B2: 1. 월 매출 500 달성 | C2: - 매일 소싱할 곳 찾기 | D2: 주 5회 | E2: - 무신사 소싱처 및 상품 2개 구매 | F2: 강의 구매 한것으로 대체 | G2: 강의 다보고 실행하기 | K2: 3 | L2: =countif(N2:AR2,"O") -> 2 | M2: =L2/K2 -> 0.66666667 | N2: O | O2: O
C3: - 주 1회 구매 시도 | D3: 주 1회 | E3: - 상품 2개 구매 완료 | G3: - 소싱하기
C4: - 구입시 기록 및 수익률 체크 | D4: 월 1회 | E4: - 크림 신발 한개 판매 완료 | G4: - 상품업로드
B5: 2, 자동화 프로그램 만들기 | C5: - 프로그래밍 책 보고 개발하기 | D5: 주 2회
C6: - 최종 프로그램 | D6: 1분기
B7: 3. 미캔 요소 1000개 올리기 | C7: - 최소한으로 자동화(+프로그램) 시켜서 주 100개 | D7: 주 1회 | E7: 총 217개 - 심사대기 79 - 요소 108개 - 거부 30개 | F7: 미드저니 0시간 만들기 하루 200개씨그리기 | G7: 승인나는대로 올리기 미드저니 활용하기 요소 잘나가는거 익히기
A8: 재테크 공부 | B8: 1. 독서 3권 , 양보다 질로 무조건 행동하기 | C8: - 한달에 한권, 무조건 행동할꺼 하나 뽑아내서 실행하기 | D8: 주 1회 | E8: - 나는 스무살의 나를 가장 존중한다 - 데일카네기의 자기개발론 | G8: 끝내결국해내는사람들
B9: 2. 부동산, 주식 신문 읽기 | C9: - 신문 or 유튜브 or 블로거 보고 매일 간단하게라도 정리하기 | D9: 주 5회 | F9: 매일 보고 간단하게 정리 메모장에라도 | G9: 매일
C10: - 경제 지표 구글 스프레드에 작성 | D10: 주 5회 | F10: 한 종목이라도 체크 해보기 | G10: 고고
B11: 3. 직원 관리 | C11: - 해당 지역 분석 하기 | D11: 주 1회 | F11: 지역 분석 다시 확인 | G11: 6개지역 분석
C12: - 역전세 대비, 공급 파악하기 | D12: 월 2회 | F12: 현재 지역 상황 확인 | G12: 매물, 공급, 전세, 시장싱황
A14: 건강 | B14: 1. 운동하기 | C14: - 달리기 or 헬스 | D14: 주 4회 | E14: 총 10회 | F14: 주 3-4회 고고 운동하면 뇌가 깬다! | G14: =F14 -> 주 3-4회 고고 운동하면 뇌가 깬다!
C15: - 인바디 체크 (근육량 36kg, 체지방 12%) | D15: 월 1회 | E15: - 근육량 34kg, 체지방률 12.5% | G15: 2월초 재보기
C16: - 운동 기록하기( 주별 무게 및 횟수 체크) | D16: 주 4회 | E16: - 홈트까지 기록 완료 | F16: . | G16: 데이터 분석해서 체계적으로
B17: 2. 비타민 챙겨먹기 | C17: - 비타민 책 읽고 정리 후 먹기 | D17: 일 1회 | E17: - 정리완료 | F17: 구매처 알아보기 | G17: 구매!
D20: N잡 수입
D21: 크림 | E21: 19600
D22: AI연금 | E22: 1615
D23: 에비 | E23: 3000000
E25: =SUM(E21:E24) -> 3021215

Sheet 2025년 1분기(수정)의 사본
B1: 1분기(목표) | C1: 세부 계획 | D1: 수치화 | E1: 1월 실적 | F1: 피드백 | G1: 2월 계획 | H1: 2월 실적 | I1: 피드백 | J1: 3월 계획 | K1: 3월 실적 | L1: 피드백 | M1: 4월 계획 | N1: 4월 실적 | O1: 피드백 | P1: 5월 계획 | Q1: 1년 목표 | R1: 5년 목표 | S1: 10년 목표 | T1: 목표 | U1: 실적 | V1: 달성률 | W1: 1 | X1: 2 | Y1: 3 | Z1: 4 | AA1: 5 | AB1: 6 | AC1: 7 | AD1: 8 | AE1: 9 | AF1: 10 | AG1: 11 | AH1: 12 | AI1: 13 | AJ1: 14 | AK1: 15 | AL1: 16 | AM1: 17 | AN1: 18 | AO1: 19 | AP1: 20 | AQ1: 21 | AR1: 22 | AS1: 23 | AT1: 24 | AU1: 25 | AV1: 26 | AW1: 27 | AX1: 28 | AY1: 29 | AZ1: 30 | BA1: 31
A2: N잡 | B2: 1. 월 매출 500 달성 | C2: - 매일 소싱할 곳 찾기 | D2: 주 5회 | E2: - 소싱처 및 상품 2개 구매 | F2: 강의 구매 한것으로 대체 | G2: 강의 다보고 실행하기 | H2: - 소싱처 및 상품 2개 구매 | T2: 3 | U2: =countif(W2:BA2,"O") -> 2 | V2: =U2/T2 -> 0.66666667 | W2: O | X2: O
C3: - 주 1회 구매 시도 | D3: 주 1회 | E3: - 상품 2개 구매 완료 | G3: - 소싱하기 | H3: - 상품 2개 구매 완료 | K3: - 상품 6개 구매 완료 | N3: - 소싱 10개 완료 | O3: 소싱을 늘리자 | P3: 소싱 20개
C4: - 구입시 기록 및 수익률 체크 | D4: 월 1회 | E4: - 신발 2개 판매 완료 | G4: - 상품업로드 | H4: - 신발 2개 판매 완료 | K4: - 신발 6개 판매 완료 | N4: - 4개 판매 완료 | P4: 일주일 물건 시세파악
C5: - 쿠팡 | J5: - 강의 듣기 | K5: - 강의 절반 들음 | M5: - 강의 완강!! | N5: - 강의완강!! | P5: 필요시
J6: - 사업자 및 입점하기 | K6: X | M6: - 사업자 및 입점하기 | N6: - 사업자 개설 | P6: 입점하기
J7: - 상품 최소 2개 올리기 | K7: X | M7: - 상품 최소 6개 올리기 | N7: X | P7: 상품 최소 2개 올리기
B8: 2, 자동화 프로그램 만들기 | C8: - 프로그래밍 책 보고 개발하기 | D8: 주 2회
C9: - 최종 프로그램 | D9: 1분기
B10: 3. 미캔 요소 1000개 올리기 | C10: - 최소한으로 자동화(+프로그램) 시켜서 주 100개 | D10: 주 1회 | E10: 총 335개 - 심사대기 18 - 요소 281개 - 거부 36개 | F10: 미드저니 0시간 만들기 하루 200개씨그리기 | G10: 승인나는대로 올리기 미드저니 활용하기 요소 잘나가는거 익히기 | H10: 총 335개 - 심사대기 18 - 요소 281개 - 거부 36개 | K10: 총 197개 - 심사대기 20 - 요소 157개 - 거부 2개 | L10: 크림이 훨 수익이 좋아 거의 시간안들이는 방향에서 올리기 | N10: 그림그리기 자동화 | O10: 수익이저조하네 | P10: 키워드분석해서 올리기
A11: 재테크 공부 | B11: 1. 독서 3권 , 양보다 질로 무조건 행동하기 | C11: - 한달에 한권, 무조건 행동할꺼 하나 뽑아내서 실행하기 | D11: 주 1회 | E11: - 나는 스무살의 나를 가장 존중한다 - 데일카네기의 자기개발론 | G11: 끝내결국해내는사람들 | H11: - 데일카네기의 자기개발론 | J11: - 결국 끝내 해내는 사람들 - 주린이 주식 투자 하기 - 마연굴 | K11: - 결국 끝내 해내는 사람들 - 주린이 주식 투자 하기 | L11: 주린이 주식 투자하기 처럼 투자하기 | M11: - ETF 책 - | N11: - 결국 해내는 사람들 - ETF로 시작하라 | O11: 실행이답이다! | P11: - 회복탄력성 -
B12: 2. 부동산, 주식 신문 읽기 | C12: - 신문 or 유튜브 or 블로거 보고 매일 간단하게라도 정리하기 | D12: 주 5회 | F12: 매일 보고 간단하게 정리 메모장에라도 | G12: 매일 | H12: - 간간히 읽고 있어서 아쉬움, 적어도 하루에 한개씩 읽기 | J12: - 적어도 하루에 한개씩 | K12: - 잘 안봄... | L12: 매일 보고 간단하게 정리 메모장에라도 | M12: - 제목만이라도 보기 | N12: - 잘 안봄... | O12: 매일 보고 간단하게 정리 메모장에라도 | P12: - 제목만이라도 보기
C13: - 주식 투자해보기 | D13: 주 5회 | F13: 한 종목이라도 체크 해보기 | G13: 고고
B14: 3. 직원 관리 | C14: - 해당 지역 분석 하기 | D14: 주 1회 | F14: 지역 분석 다시 확인 | G14: 6개지역 분석 | H14: 포항, 청주 매도 내놓음 - 시장상황 파악 중 - - 포항은 전세를 다시 맞출 것 같고, 청주는 가격을 낮춰서도라도 매도할 생각 | J14: - 포항, 청주 대출 알아보기 - 포항, 청주 시나리오 작성 - 시장 상황 꾸준히 파악 및 일지 작성 | K14: - 청주 사업자 대출 O - 포항 은행 대출 O | L14: 대출 알아봐야 할듯... | M14: - 포항 사업자 대출 알아보기 - 포항 대출 실행 - 금액 시나리오 재 작성 | N14: - 포항 주담대 - 포항 전세세입자 - 청주 주담대 - 청주 매도 | P14: - 포항 세입자 계약 및 대출 상환 - 청주 세입자 보증금 반환 - 올해 전세재계약 확인
C15: - 역전세 대비, 공급 파악하기 | D15: 월 2회 | F15: 현재 지역 상황 확인 | G15: 매물, 공급, 전세, 시장싱황 | K15: - 포항 전세 수요꾸준히 - 청주 매매 수요 없음... | L15: 현재 지역 상황 확인 | M15: 현재 지역 상황 확인 | N15: - 울산 긍정적 | O15: 현재 지역 상황 확인 | P15: 현재 지역 상황 확인
B16: 4. 강의 | C16: - 무엇이든 배우자! | K16: - 쿠팡강의 | N16: - ADsP
K17: - 손품왕 기술적 분석 무료특강
A19: 건강 | B19: 1. 운동하기 | C19: - 달리기 or 헬스 | D19: 주 4회 | E19: 총 10회 | F19: 주 3-4회 고고 운동하면 뇌가 깬다! | G19: =F19 -> 주 3-4회 고고 운동하면 뇌가 깬다! | H19: - 주 3-4회는 못하고 2-3회 운동중 | J19: 주 3-4회 | K19: - 주 3-4회는 못하고 2-3회 운동중 | L19: 약먹어도 낫지 않으면 다시 주사 | M19: 주 3-4회 | N19: - 주사 또 맞음.. | O19: 약먹어도 낫지 않으면 다시 주사 | P19: 5월중 복구
C20: - 인바디 체크 (근육량 36kg, 체지방 12%) | D20: 월 1회 | E20: - 근육량 34kg, 체지방률 12.5% | G20: 2월초 재보기
C21: - 운동 기록하기( 주별 무게 및 횟수 체크) | D21: 주 4회 | E21: - 홈트까지 기록 완료 | G21: 데이터 분석해서 체계적으로
B22: 2. 비타민 챙겨먹기 | C22: - 비타민 책 읽고 정리 후 먹기 | D22: 일 1회 | E22: - 정리완료 | F22: 구매처 알아보기 | G22: 구매!
D25: N잡 수입
D26: 크림 | E26: 42100 | F26: 25300 | H26: 60000 | K26: 80200 | N26: 32000
D27: AI연금 | E27: 3012 | H27: 6347 | K27: 4830 | N27: 4066
D28: 머니메이커스 | N28: 40000
D29: 에비 | E29: 2000000 | H29: 1464177 | K29: 4000000 | N29: 2415000
E31: =SUM(E26:E30) -> 2045112 | H31: =SUM(H26:H30) -> 1530524 | K31: =SUM(K26:K30) -> 4085030 | N31: =SUM(N26:N30) -> 2491066

Sheet 시트9
B5: 부동산 | C5: 청주매도
C6: 구미 도어락수리
C7: 청주양도세 가산세
C8: 행신전세연장
B14: 투자 | C14: 주식
C15: 부동산
C16: AI | D16: AI강의 6개 수강완료
B19: 모임 | C19: 위브즈
C20: 머니메이커스
C21: 사업자모임
B23: 대출 | C23: 소상공인대출연장
B27: 회사 | C27: SPA시험

Sheet 2025년 만다라트
B2: OO의 만다라트 ver.2023
B4: 자랑스러운 아빠되기 | C4: 서울 준신축 아파트 매수 | D4: 와이프와 월1회이상 데이트 | E4: 년4회 부모님 찾아뵙기 | F4: 집근처로 부모님이사 | G4: 부모님 가게차려 드리기 | H4: 주 2-3회 헬스장 다니기 | I4: 최대한 좋음 음식먹기 | J4: 40,50대 바디프로필 촬영
B5: 50세이후 월 400지출자금만들기 | C5: =E7 -> 가족 | D5: 연2회 가족여행 | E5: 아버지와 바다낚시 | F5: =F7 -> 부모님 | G5: 연1회 건강검진 | H5: 부모님 건강 챙기기 | I5: =G7 -> 건강 | J5: 와이프 운동 끊어주기
B6: 아이들 경제공부 | C6: 아이공부 | D6: 와이프 사업지원 | E6: 어머니 하고싶은일 만만들기 | F6: 부모님 건강취미 만들기 | G6: 연2회이상 여행가기 | H6: 과식줄이기 | I6: 몸매유지 | J6: 근력키우기
B7: 친구들과 만남 | C7: 영향력있는 사람들 월1회 만남 | D7: 재능기부 | E7: 가족 | F7: 부모님 | G7: 건강 | H7: 역전세 현명하게 대처하기 | I7: 최소 1년에 1채 | J7: 한달에 하나 임장보고서
B8: 투자쪽에서 최고가되기 | C8: 행복 | D8: 기부 | E8: 행복 | F8: N잡 월 5천 매출 달성 | G8: 부동산 투자 | H8: 월부강의 꾸준히듣기 | I8: =G8 -> 부동산 투자 | J8: 1일1개이상 카페글 읽기
B9: 하루하루 알차게 보내기 | C9: 가족& 부모님과 여행 | D9: 배움 | E9: 투자 공부 | F9: 파이프라인 | G9: 가게 월 순수익 천만원 | H9: 세금공부 | I9: 시세트래킹 | J9: 투자복기
B10: 1년 52권 목표 | C10: 투자관련 강의듣기 | D10: 신문 1일1회 | E10: 나만의 브랜딩 갖기 | F10: 지인과 꾸준히활동 | G10: SNS활동 | H10: 5천만원 매출올리기 | I10: 관련 책 다 읽기 | J10: 우리가게 적용시켜보기
B11: 시금부작성 | C11: =E9 -> 투자 공부 | D11: 재테크 모임활동 | E11: 모든일 연관지어보기 | F11: =F9 -> 파이프라인 | G11: 50세이후 월 400지출 자금만들기 | I11: =G9 -> 가게 월 순수익 천만원 | J11: 주변 관련 강의 듣기
B12: 몸값올리기 | C12: 좋은인맥 만들기 | D12: 영향력있는 유튜브구독 | E12: 신문 1일1회 | F12: 최신 Trend 공부 | G12: 사업 | I12: 시스템화 시키기 | J12: 장사 마인드 책 읽기

Sheet 2023년 만다라트
B2: OO의 만다라트 ver.2023
B4: 자랑스러운 아빠되기 | C4: 서울 준신축 아파트 매수 | D4: 와이프와 월1회이상 데이트 | E4: 년4회 부모님 찾아뵙기 | F4: 집근처로 부모님이사 | G4: 부모님 가게차려 드리기 | H4: 주 2-3회 헬스장 다니기 | I4: 최대한 좋음 음식먹기 | J4: 40,50대 바디프로필 촬영
B5: 50세이후 월 400지출자금만들기 | C5: 가족 | D5: 연2회 가족여행 | E5: 아버지와 바다낚시 | F5: 부모님 | G5: 연1회 건강검진 | H5: 부모님 건강 챙기기 | I5: 건강 | J5: 와이프 운동 끊어주기
B6: 아이들 경제공부 | C6: 아이공부 | D6: 와이프 사업지원 | E6: 어머니 하고싶은일 만만들기 | F6: 부모님 건강취미 만들기 | G6: 연2회이상 여행가기 | H6: 과식줄이기 | I6: 몸매유지 | J6: 근력키우기
B7: 친구들과 만남 | C7: 영향력있는 사람들 월1회 만남 | D7: 재능기부 | E7: 가족 | F7: 부모님 | G7: 건강 | H7: 역전세 현명하게 대처하기 | I7: 최소 1년에 1채 | J7: 한달에 하나 임장보고서
B8: 투자쪽에서 최고가되기 | C8: 행복 | D8: 기부 | E8: 행복 | F8: 100억 달성 | G8: 부동산 투자 | H8: 월부강의 꾸준히듣기 | I8: 부동산 투자 | J8: 1일1개이상 카페글 읽기
B9: 하루하루 알차게 보내기 | C9: 가족& 부모님과 여행 | D9: 배움 | E9: 투자 공부 | F9: 파이프라인 | G9: 가게 월 순수익 천만원 | H9: 세금공부 | I9: 시세트래킹 | J9: 투자복기
B10: 1년 52권 목표 | C10: 투자관련 강의듣기 | D10: 신문 1일1회 | E10: 나만의 브랜딩 갖기 | F10: 지인과 꾸준히활동 | G10: SNS활동 | H10: 5천만원 매출올리기 | I10: 관련 책 다 읽기 | J10: 우리가게 적용시켜보기
B11: 시금부작성 | C11: 투자 공부 | D11: 재테크 모임활동 | E11: 모든일 연관지어보기 | F11: 파이프라인 | G11: 50세이후 월 400지출 자금만들기 | I11: 가게 월 순수익 천만원 | J11: 주변 관련 강의 듣기
B12: 몸값올리기 | C12: 좋은인맥 만들기 | D12: 영향력있는 유튜브구독 | E12: 신문 1일1회 | F12: 최신 Trend 공부 | G12: 사업 | I12: 시스템화 시키기 | J12: 장사 마인드 책 읽기

Sheet 5월계획
B2: 2분기(목표) | C2: 세부 계획 | D2: 수치화 | E2: 1년 목표 | F2: 5년 목표 | G2: 10년 목표 | H2: 목표 | I2: 실적 | J2: 달성률 | K2: 1 | L2: 2 | M2: 3 | N2: 4 | O2: 5 | P2: 6 | Q2: 7 | R2: 8 | S2: 9 | T2: 10 | U2: 11 | V2: 12 | W2: 13 | X2: 14 | Y2: 15 | Z2: 16 | AA2: 17 | AB2: 18 | AC2: 19 | AD2: 20 | AE2: 21 | AF2: 22 | AG2: 23 | AH2: 24 | AI2: 25 | AJ2: 26 | AK2: 27 | AL2: 28 | AM2: 29 | AN2: 30 | AO2: 31
A3: 가족 | B3: 1. 와이프와 한달 1회 데이트 | C3: - 매주 4째주 일요일(변동 가능) | D3: 월 1회 | H3: 3 | I3: =countif(K3:AO3,"O") -> 2 | J3: =I3/H3 -> 0.66666667 | K3: O | L3: O
B4: 2, 월 1회 재무 상황 공유 | C4: - 매월 마지막 일 | D4: 월 1회
A7: 부모님 | B7: 1. 주 1회 화상 통화 | C7: - 매주 일요일 | D7: 주 1회
B8: 2. 필요 물품 파악 | C8: - 항시 | D8: 일 1회
B9: 3. 건강 체크 | C9: - 건강검진 (년1회)
B10: 4. 아파트 마련해드리기
D11: 연 1회
A12: 건강 | B12: 1. 5/20 바디프로필 촬영 | C12: - 2주마다 인바디 체크 | D12: 일 1회
C13: - 잠자기 4시간전 음식 섭취 금지 | D13: 일 1회
B15: 2. 비타민 챙겨먹기 | C15: - 아침 공복 프로바이오틱스 | D15: 일 1회
C16: - 점심 식사 후 비타맥스 | D16: 일 1회
B17: 3. 최소 주 3회 이상 운동 | C17: - 출근 전 or 출근 후 헬스 장 | D17: 일 1회
C18: - 주별 무게 및 횟수 체크 | D18: 주 1회
A19: 행복 | B19: 1. 배움 | C19: - 가게 관련 강의 듣기(마케팅, 자영업자 등등) | D19: 월 1회
A22: 부동산 투자 | B22: 1. 내 물건 지키기 | C22: - 매주 KB 시세 체크 | D22: 주 1회
C23: - 감당 가능 금액 파악하기 ( 대출 및 최대 대출 이자 감당 가능여부 확인) | D23: 1회
C24: - 사업자 대출 알아보기
C25: - 하나씩 대응 하면서 전세 계약 대응하기 | D25: 주 1회
B26: 2. 시세트래킹 | C26: - 2번째 4번째주 수요일 시세트래킹 | D26: 주 2회
B27: 3. 앞마당 늘리기 | C27: - 매월 최소 1개 이상 앞마당 만들기 | D27: 월 1개
A28: 투자 공부 | B28: 1. 독서 | C28: - 월 4권 읽기 | D28: 주 1권 | E28: 벤치마킹 30개 이상 실행
B29: 2. 월부 TV or 실전 경험담 or 튜터님 글 보기 | C29: - 매일 1개 | D29: 일 1회
B30: 3. 뉴스 보기 | C30: - 매일 부동산 관련 뉴스 보기 | D30: 일 1회
A31: 파이프라인 | B31: 1. 부수입 만들기 | C31: - 부수입 항목 설정 | D31: 월 1회
A34: 가게 월 순수익 천만원 | B34: 1. 마케팅 공부 | C34: - 마케팅 관련 책 보기 | D34: 주 1회
C35: - 필요시 강의 듣기 | D35: 월 1회
B36: 2. 가게 일 돕기 | C36: - 가게 현황 파악 (손님, 가게 상태, 필요 물품 등) | D36: 주 1회

Sheet 만다라트 월간계획표
A1: 만다라트
A2: ='2023년 만다라트'!E7 -> 가족 | B2: ='2023년 만다라트'!F7 -> 부모님 | C2: ='2023년 만다라트'!G7 -> 건강 | E2: 암시(나를 이끄는 방향성) | V2: 나에게 힘을 주는 글 OR 내가 투자를 해야 하는 이유
A3: ='2023년 만다라트'!E8 -> 행복 | B3: ='2023년 만다라트'!F8 -> 100억 달성 | C3: ='2023년 만다라트'!G8 -> 부동산 투자
A4: ='2023년 만다라트'!E9 -> 투자 공부 | B4: ='2023년 만다라트'!F9 -> 파이프라인 | C4: ='2023년 만다라트'!G9 -> 가게 월 순수익 천만원
A6: 역산 스케쥴링
A7: 년간목표 (실천과제) | B7: 수치입력 | C7: 분기(3개월) | D7: 1달 | E7: 1주 | G7: 1일 | I7: 년간목표 (실천과제) | M7: 수치입력 | P7: 분기(3개월) | S7: 1달 | U7: 1주 | W7: 1일 | Y7: 년간목표 (실천과제) | AC7: 수치입력 | AF7: 분기(3개월) | AI7: 1달 | AK7: 1주 | AM7: 1일
A8: 와이프와 한달 1회 데이트 | I8: 배움 - 강의듣기
A9: 월 1회 재무 상황 공유
A11: 주 1회 화상 통화
A12: 아파트 마련 해드리기
A13: 건강 체크
A14: 헬스장가기
A15: 칼로리 맞춰먹기
A18: 월간 계획표 | P18: 1만 시간의 법칙
A19: 우선순위 | B19: 목표 | D19: 예상소요기간 | E19: 실적 | K19: 실제소요기간 | N19: 달성률 | P19: 지난 나의 투자시간 | U19: ='[양식] 월간/목실시금부'!D38 -> #REF! | X19: 이번달 투자시간 | AA19: ='[양식] 월간/목실시금부'!D39 -> #REF!
P20: 주차별 투자시간 | U20: 목표 | X20: 실적 | AA20: 달성률
P21: 1주차 투자시간 | U21: ='[양식] 월간/목실시금부'!C41 -> #REF! | X21: ='[양식] 월간/목실시금부'!D41 -> #REF! | AA21: =X21/U21 -> #REF!
P22: 2주차 투자시간 | U22: ='[양식] 월간/목실시금부'!C42 -> #REF! | X22: ='[양식] 월간/목실시금부'!D42 -> #REF! | AA22: =X22/U22 -> #REF!
P23: 3주차 투자시간 | U23: ='[양식] 월간/목실시금부'!C43 -> #REF! | X23: ='[양식] 월간/목실시금부'!D43 -> #REF! | AA23: =X23/U23 -> #REF!
P24: 4주차 투자시간 | U24: ='[양식] 월간/목실시금부'!C44 -> #REF! | X24: ='[양식] 월간/목실시금부'!D44 -> #REF! | AA24: =X24/U24 -> #REF!
P25: 5주차 투자시간 | U25: ='[양식] 월간/목실시금부'!C45 -> #REF! | X25: ='[양식] 월간/목실시금부'!D45 -> #REF! | AA25: =X25/U25 -> #REF!
A27: 주차별 실적 현황 | E27: 1주차 목표 | K27: 실적 | L27: 2주차 목표 | R27: 실적 | S27: 3주차 목표 | Y27: 실적 | Z27: 4주차 목표 | AF27: 실적 | AG27: 5주차 목표 | AM27: 실적
A28: 주차 | B28: 목표 | C28: 실적 | D28: 달성률 | K28: O | R28: O | Y28: O | AF28: O | AM28: O
A29: 1주차 | B29: =COUNTA(E28:J33) -> 0 | C29: =COUNTA(F28:K33) -> 1 | D29: =C29/B29 -> #DIV/0!
A30: 2주차 | B30: =COUNTA(L28:Q33) -> 0 | C30: =COUNTA(M28:R33) -> 1 | D30: =C30/B30 -> #DIV/0!
A31: 3주차 | B31: =COUNTA(S28:X33) -> 0 | C31: =COUNTA(T28:Y33) -> 1 | D31: =C31/B31 -> #DIV/0!
A32: 4주차 | B32: =COUNTA(Z28:AE33) -> 0 | C32: =COUNTA(AA28:AF33) -> 1 | D32: =C32/B32 -> #DIV/0!
A33: 5주차 | B33: =COUNTA(AG28:AL33) -> 0 | C33: =COUNTA(AH28:AM33) -> 1 | D33: =C33/B33 -> #DIV/0!
A35: 세부목표 | B35: 실천과제 | C35: 월목표 | D35: 달성률 | E35: 1 | F35: 2 | G35: 3 | H35: 4 | I35: 5 | J35: 6 | K35: 7 | L35: 8 | M35: 9 | N35: 10 | O35: 11 | P35: 12 | Q35: 13 | R35: 14 | S35: 15 | T35: 16 | U35: 17 | V35: 18 | W35: 19 | X35: 20 | Y35: 21 | Z35: 22 | AA35: 23 | AB35: 24 | AC35: 25 | AD35: 26 | AE35: 27 | AF35: 28 | AG35: 29 | AH35: 30 | AI35: 31
A36: =A2 -> 가족 | C36: 31 | D36: =COUNTA(E36:AI36)/C36 -> 0
C37: 31 | D37: =COUNTA(E37:AI37)/C37 -> 0
C38: 31 | D38: =COUNTA(E38:AI38)/C38 -> 0
A39: =B2 -> 부모님 | C39: 31 | D39: =COUNTA(E39:AI39)/C39 -> 0
C40: 31 | D40: =COUNTA(E40:AI40)/C40 -> 0
C41: 31 | D41: =COUNTA(E41:AI41)/C41 -> 0
A42: =C2 -> 건강 | C42: 31 | D42: =COUNTA(E42:AI42)/C42 -> 0
C43: 31 | D43: =COUNTA(E43:AI43)/C43 -> 0
C44: 31 | D44: =COUNTA(E44:AI44)/C44 -> 0
A45: =A3 -> 행복 | C45: 31 | D45: =COUNTA(E45:AI45)/C45 -> 0
C46: 31 | D46: =COUNTA(E46:AI46)/C46 -> 0
...

Sheet 독서계획
B3: 년도 | C3: 월 | D3: 분야 | E3: 책 제목 | F3: 내용 | G3: BM | H3: 실행여부
B4: 2023 | C4: 1월
C8: 2월
C12: 3월
C16: 4월

Sheet 끄적끄적
G3: ★ 3월 계획
B5: 부동산 | C5: - 월간 모의투자 | G5: ================================== -> #ERROR!
C6: - 시세트래킹 | G6: -------------------
G7: ★★ 또기 ★★ |
G8: -------------------
G9: ☆ 2월 실적
C10: 여행 | D10: 100억 | E10: 마카롱
G11: ※ N잡
G12: ㅁ 크림
G13: - 2월 소싱 : 130만원
G14: - 2월 판매수익 : 6만원
G15: - 총 누적 수익 : 16.5만원
G17: ㅁ 쿠팡
G18: - 강의 못들음.. 반성
G20: ㅁ 미캔
G21: - 2월 요소 : 502개
G22: - 2월 거부 : 5개
G23: - 2월 총그림 : 507개
G24: - 누적 요소 : 1,055개
... G82: ㅁ 운동하기 (주 3-4회)

Sheet 23년 상반기 결산
C2: 1월 | D2: 2월 | E2: 3월 | F2: 4월 | G2: 5월 | H2: 6월 | I2: 7월 | J2: 8월 | K2: 9월 | L2: 10월 | M2: 11월 | N2: 12월
B3: 부동산 | C3: 대구 | D3: 당진 | E3: 송파구 | F3: 포항 전세 연장 완료 | G3: 금천구, 관악구, 강동구 | H3: 성동구, 광진구, 동대문구 | I3: 동작구, 영등포구 | J3: 양천구, 강서구, 구로구 | K3: 성북구, 중랑구 | L3: 강북구, 도봉구 | M3: 노원구 | N3: 행신 전세 완료
G4: 청주 전세 연장 완료 | J4: 울산 전세 연장 완료 | N4: 용산구
B6: 강의 | C6: 월부학교 | D6: 월부학교 | E6: 월부학교 | G6: 숀군 대출 특강 | H6: 직딩 - 네이버 마이플레이스 | I6: 유나바머 | J6: 유나바머
H7: 북극성주 - 기초강의 | J7: 퀀트 강의
B9: 가게 | F9: 네이버 마이플레이스 셋팅 | G9: 스마트스토어 홍보 | H9: 네이버 광고 신청 | I9: 네이버 광고, 지역소상인 광고 | K9: 마카롱, 휘낭시에 CPC 광고 | M9: 쿠팡 입점 | N9: 아이디어스 입접
F10: 네이버 톡톡 신청 | G10: 네이버 리뷰 천원 홍보 | H10: 인스타 릴스 시작 | M10: G마켓, 옥션 입점
F11: 네이버 예약 셋팅
F12: 네이버 포장 셋팅
B14: 독서 | C14: 야 너두 할 수 있어 | D14: 후회의 재발견 | E14: 부동산 공부할 결심 | F14: 부동산 투자 인사이트 | G14: 부의 레버리지 | H14: 게으르지만 컨테츠로 돈을 잘 법니다 | I14: 스토리의 과학 | J14: 10배의법칙 | K14: 가장 효율적인 부동산 투자법 | L14: 생각의비밀 | M14: 부동산투자의관점 | N14: 1%읽는힘
C15: 아주 작은 습관의 힘 | D15: 사람은 무엇을 성장하는가 | E15: 모든것은 기본에서 시작한다 | G15: 사장학개론 | H15: 만화로 보는 회계학 | M15: 당장 써먹는 온라인콘텐츠
E16: 유수연의 독설 | H16: 당신의 생각을 정리해드립니다.
B18: 건강 | G18: 바디프로필 촬영 완료 | H18: 체지방율 유지 12% 이하 - 현재 13%
H19: 주 4회 이상
B21: 파이프라인 | C21: 부동산 기초 강의 | D21: 부동산 기초 강의 | E21: 부동산 기초 강의 | F21: 부동산 기초 강의 | I21: 텀블러백 판매 준비 | J21: 텀블러백 판매 시작 | L21: 네이버 광고 | M21: 쿠팡 입점 | N21: 블로그 작성 시작

Sheet 23년 실적
B2: 23년 | C2: 부동산 | D2: 강의 | E2: 가게 | F2: 파이프라인 | G2: 독서 | H2: 건강 | I2: 가족
B3: 은둥 | E3: 스마트스토어 오픈 | I3: 부모님 영상통화
E4: 아이디어스 입점 | I4: 미래계획
E5: 쿠팡입점 | I5: 임신준비중
E6: 쿠팡이츠/배민/땡겨요/요기요/ 네이버주문 입점 | I6: 엽산챙겨먹기
E7: 스마트스토어 광고돌리기 | I7: 건강검진
E8: 추석시즌 디저트 | I8: 일요일은 둘이서 보내기
E9: 빼빼로데이 디저트 | I9: 존중하며 표현 잘하기
E10: 크리스마스 디저트
E11: 목표 월 600달성
B13: 덕 | C13: 올해 전세 연장 (4/6) | D13: 부동산 강의 4개 완료 | E13: 네이버메이플레스 셋팅 | F13: 부동산기초강의 ㄴ 230만원 | G13: 총 20권 완료 | H13: 바디프로필 촬영 완료 | I13: 주 1회 부모님 통화
C14: 역전세 -1.25억 | D14: 월부학교, 숀군대출 | E14: 스마트스토어 개설 | F14: 텀블러백 판매 ㄴ 25만 | H14: 건강 유지 ㄴ 현재 체지방율 15% | I14: 집 이사 보류
C15: 임장지 20개 완료 | D15: 북극성주, 유나바머 | E15: 다채널 입점(쿠팡, 아이디어스) | F15: 블로그 작성 시작
E16: 월매출 200~500
B18: 24년
B19: 은둥
B24: 덕 | C24: 전세 2건 잘 마무리 | D24: 부동산 강의 재수강 ㄴ 북극성주, 유나바머 | E24: 네이버메이플레스 셋팅 | F24: 부동산기초강의 ㄴ 230만원 | G24: 총 20권 완료 | H24: 바디프로필 촬영 완료 | I24: 주 1회 부모님 통화
C25: 이익난거 매도하기 | D25: 부동산 책 보고 정리하기 | E25: 스마트스토어 개설 | F25: 텀블러백 판매 ㄴ 25만 | H25: 건강 유지 ㄴ 현재 체지방율 15% | I25: 집 이사 보류
C26: 수도권 임장지 넓히기 | D26: 부동산 대부들 블로그 보고 인사이트 얻기 | E26: 다채널 입점(쿠팡, 아이디어스) | F26: 블로그 작성 시작
E27: 월매출 200~500

Sheet 시트7
C2: 23년 | E2: 24년
B3: 23년 | C3: 은둥 | D3: 덕 | E3: 은둥 | F3: 덕
B4: 부동산🎪 | D4: 올해 전세 연장 (4/6) 역전세 -1.25억 임장지 20개 완료 | F4: 전세 2건 잘 마무리 이익난거 매도하기 수도권 임장지 넓히기
B5: 강의📊 | D5: 부동산 강의 4개 완료 월부학교, 숀군대출 북극성주, 유나바머 | E5: - 스토어 강의 듣고 같이 공유 | F5: 부동산 강의 재수강 ㄴ 북극성주, 유나바머" 부동산 책 보고 정리하기 부동산 대부들 블로그 보고 인사이트 얻기
B6: 가게📠 | C6: 스마트스토어 오픈 아이디어스 입점 쿠팡입점 쿠팡이츠/배민/땡겨요/요기요/ 네이버주문 입점 스마트스토어 광고돌리기 추석시즌 디저트 빼빼로데이 디저트 크리스마스 디저트 목표 월 600달성 | D6: 네이버메이플레스 셋팅 스마트스토어 개설 다채널 입점(쿠팡, 아이디어스) 월매출 200~500 | E6: - 온라인으로 전향하기 ㄴ 1년 운영해보니 시즌 상품이 대부분 온라인에서 잘 팔리는편. ㄴ 오프라인은 적음. 오프라인은 일 매출이 적고, ㄴ 월세는 위치에 비해 비싸기 때문에 온라인을 더 키워서 ㄴ 오프라인은 접고 온라인공간으로 가깝고 저렴한 곳으로 1년정도 연장 ㄴ 아이도 생길예정이기 때문에 생각해볼 필요있음. - 스토어 / 아이디어스 공부 및 광고하기 - 답례품 상품을 늘려서 자주 노출하기 - 11월 계약 만료전에 해보고싶은거 다 후회없이 해보기! - 옮길지 연장할지 새로운곳 계약할지 계획. | F6: - 월 매출 1000만원 - 다채널 11개 입점 - 가게 이사? - 카카오톡 선물 입점!
B7: 파이프라인💰 | D7: "부동산기초강의 ㄴ 230만원" "텀블러백 판매 ㄴ 25만" 블로그 작성 시작 | E7: - 에어비앤비 적어도 1개 계약 - 스마트스토어 오픈하기 (미우마카롱말고 - 사업자들 모임 | F7: - 부동산기초 강의 ㄴ 연 500만원 - 텀블러백 다채널 등록 ㄴ 월 100만원 순이익 - 에어비앤비 ㄴ 1개 창업 - 온라인 유통사업 ㄴ 월 매출 500만원
B8: 독서📖 | D8: 총 20권 완료 | E8: - 2개월 1권 읽기 | F8: - 최소 월 2권 이상 ㄴ 연 30권 목표 - 30개의 실행 목록 만들기
B9: 건강🥋 | D9: 바디프로필 촬영 완료 "건강 유지 ㄴ 현재 체지방율 15%" | E9: - 필라테스 | F9: - 과식하지 않기 - 술 필요시에만 먹기 주1-2회 - 운동 주 4회 - 근육량 35kg, 체지방율 12% 이하
B10: 가족👨‍👨‍👧‍👦 | C10: 부모님 영상통화 미래계획 임신준비중 엽산챙겨먹기 건강검진 일요일은 둘이서 보내기 존중하며 표현 잘하기 | D10: 주 1회 부모님 통화 집 이사 보류 | E10: - 영상통화 자주 드리기 - 험한일 그만하실수 있도록 새로운 직업 및 방법 찾아보기. - 건강검진 싹 한번 해드리기. - 귀여운 우리 2세가 생김!!! | F10: - 부모님과 1회 여행 - 우리집 이사 - 우리 아이 >_<

Sheet 덕_2026
A1: 덕 2026년 연간계획
A3: 최종 목표
A4: - 내가 원하는 시간에 원하는 사람과 원하는 것을 원하는 곳에서 먹고 있다.
A5: - 100억 자산가
A6: - 배운 지식을 나누는 삶
A7: - 좋아하는 사람들과 월 1회 파티 모임
A8: - 근처에 사는 부모님과 분기별 여행
A9: - 친척들과 함께하는 가족 기업 및 사업
A12: 2026년 전략
A13: - 나는 매년 성장한다
A14: - 부동산 저평가를 알고 투자할 곳을 알고 있다
A15: - 온라인 유통으로 억 매출을 달성하고 있다
A21: 1년 로드맵
A22: 분류 | B22: 2026년 목표 | C22: 상반기목표 | D22: 1분기 | E22: 1월 | F22: 2월 계획 | G22: 2월 실적 | H22: 3월 계획 | I22: 3월 실적 | J22: 2분기 | K22: 4월 | L22: 5월 | M22: 6월 | N22: 상반기 실적 | O22: 하반기목표 | P22: 3분기 | Q22: 7월 | R22: 8월 | S22: 9월 | T22: 4분기 | U22: 10월 | V22: 11월 | W22: 12월
A23: 부동산🎪 | B23: 전세2건 마무리 | C23: 구미 전세 재계약 | E23: 구미 전세 재계약 중 | F23: 전세 1건 마무리 하반기 전세 세입자 연락.. | H23: 하반기 전세 세입자 전략짜기 | I23: 구미 전세 500 돌려줌 울산세입자 연락옴 현시세 맞춰달라했으나 잘 설득해서 기존과 동일하게 연장 | K23: 부동산자산관리시스템 개발 | N23: 포항 전세 계약 | O23: 1개 전세 재계약
B24: 이익난거 매도하기 | C24: 수익률 정해서 매도 계획 추이 확인하기 | E24: 일단 집을 다 팔아야 하나.. 지금 너무 늦은건 아닐까? | H24: 바이브코딩으로 시장상황 Report 받기 | I24: 부동산자산관리시스템 개발 중 | K24: 각 자산 트래킹 매도 하기 | N24: 청주 매도 | O24: 수익률 정해서 매도 계획 추이 확인하기
E25: - 진솔이 집알아봐주고 매매까지 | K25: 관악푸르지오 10월 11월? 만기 에어비앤비 8월 만기...
A27: 강의📊 | B27: AI 강의 | C27: 강의 1개 | E27: 강의 못들음... 왜케 바빠? | F27: AI 강의 1개 | I27: AI 관련 책 보는 중 - 어쨋든 바이브 코딩 | K27: 오픈클로 책 사서 보는중 - 따라해보기 66챌에 AI 강의하기 | N27: - 손품왕 기술적 분석 무료특강 | O27: 강의 1개
B28: 흥부 재개발재건축 강의 | C28: 강의 듣기 | I28: 5월에... | K28: 5월에.. | O28: 부동산 책 보고 정리
B29: 부동산 대부들 블로그 보고 인사이트 얻기 | C29: 숙주나물, 부룡 등등 보고 블로그 작성 주 1회 | E29: 꾸준히 보는중!!! 사람들 참 대단해.. | I29: 이거 볼시간이 왜이렇게 안나지.. 글만 쓱 읽으면 되는데 하루에 5개만이라도 | K29: 하루에 5개 글 보고 정리하기 | O29: 숙주나물, 부룡 등등 보고 블로그 작성 주 1회 | P29: 12회 | Q29: 4회 | R29: 4회 | S29: 4회 | T29: 12회 | U29: 4회 | V29: 4회 | W29: 4회
B30: 서재형 담샘 강의 | H30: 주식 강의 신청한거 내 것으로 체득화 하기 - 강의 내용 정리 - 유튜브와 내용 비교해보기 - 나만의 기준으로 기업찾아보고 분석하기 | I30: 매일 매일 보는 중 | K30: - 강의 내용 정리하기 - 유튜브와 내용 비교하기
A32: 주식 | B32: Class101 주식 강의 하나 듣기 | E32: 아직 못들음 | N32: - 주식 관련 책 + 추천 - 추천 마이너스.. - ETL 매수
B33: 마연굴 포트폴리오 운영 | E33: 1월에 운영중! - ISA에 100만원 투자금액 : 100만원, 1.41 수익률 - 새로운 연금저축에 100만원 투자 안하는중 투자 고고 - 퇴직연금 및 성과급 DC로 전환 매수금액 : 3,652,407원 수익률 0.99% | I33: 3월 미국 이란 전쟁으로 추가 매수 - ISA에 100만원 투자금액 : 100만원, 1.41 수익률 - 새로운 연금저축에 100만원 투자 안하는중 투자 고고 - 퇴직연금 및 성과급 DC로 전환 매수금액 : 3,652,407원 수익률 0.99%
B34: 민재 주식 공유한거 분석하기 | E34: 제대로 못보는중 날잡아 보기엔 시간이 안될것 같은데.. | H34: 수익률 70% - 주식 기록하는거 만들어보기
B35: 서재형담샘 분석 및 마인드 장착하기 | E35: 매일꾸준히 듣는중 | G35: 서재형 담샘 주식강의 수강!! | H35: 매수 하기 | I35: - 서재형 담샘 아침 방송 매일 듣는중 - 강의는 제대로 못보고 있음 이제 1강 완료
B36: 한경유튜브 및 신문 매일 읽기 | E36: 매일꾸준히 듣는중 | H36: 한경유튜브 및 신문 매일 읽기 | I36: 둘다 못하는중.. 민재 주식과 서재형담샘 듣기도 바쁘네.. | K36: 그래도 한번 해보자 일일 고고 체크도 해봐야겠다
A38: 파이프라인💰 | B38: 온라인 유통 사업 월 1천 매출 | C38: 월 1천 매출 | E38: 시도 언제해보지.. | K38: 크림 재고 가격 계산해보기 | N38: - 40만원 - 매일 소싱처 찾기 - 최소 100이상 구매 | O38: 월 2천 매출
B39: 에어비앤비에서 부가적인 사업 아이템 발굴 | E39: 이것도 해야하고 ㅋㅋ | N39: - 3만원 - 보류 중, 자동이니 할까?
B40: 에비 1개더? | E40: 언제..?
A42: 모임 👩🏼‍🤝‍👩🏼 | B42: 한가해보이님독서모임 | K42: 4/26(일) 예정된 전쟁
B43: 매너남독서모임 | K43: 4/15(수) 진보를 위한 주식투자
B44: 부독모독서모임 | K44: 4/26(일) 박태웅의 AI 강의 2026
B45: 머니메이커스독서모임
B46: 위브즈 투자모임 | L46: 5/10(일) 정기모임
B47: 66챌 투자모임
B48: 부추 투자모임
A50: 독서📖 | B50: 최소 월 1권 이상 읽기 | C50: 12권 | D50: 6권 | E50: - 마법의 연금 굴리기 - 팩트풀니스... (안읽음..) | G50: 2권 완독 - 나는 노후에 가난하지 않기로 결심했다. - 월사남 | H50: 부의 원리 - 밥프록터 | K50: - 밥브록터 - 부의 원리 - 오픈클로 | L50: 2권 | M50: 2권 | N50: 8권 - 회복탄력성 - 결국 해내는 사람들 - ETF로 시작하라 - 결국 끝내 해내는 사람들 - 주린이 주식 투자 하기 - 나는 스무살의 나를 가장 존중한다 - 데일카네기의 자기개발론 | O50: 12권 | P50: 6권 | Q50: 2권 | R50: 2권 | S50: 2권 | T50: 6권 | U50: 2권 | V50: 2권 | W50: 2권
B51: 연 30권 목표 | C51: 15권 | D51: 7권 | L51: 2권 | M51: 3권 | O51: 15권 | P51: 7권 | Q51: 2권 | R51: 3권 | S51: 2권 | T51: 8권 | U51: 3권 | V51: 2권 | W51: 3권
B52: 12개의 이상 실행 목록 만들고 달성 | C52: 15개 실행 완료 | D52: 7개 | E52: 마연굴읽고 포트폴리오대로 매수 완료! | L52: 2개 | M52: 3개 | N52: 월별 목록 정리 후 실행 목표 | O52: 15개 실행 완료 | P52: 7개 | Q52: 2개 | R52: 3개 | S52: 2개 | T52: 8개 | U52: 3개 | V52: 2개 | W52: 3개
A54: AI🧠 | B54: AI 프로그램 개발 | I54: - 부동산 자산관리 프로그램 - 개발중 - 가족 냉장고 관리 프로그램 - 개발중 - 오픈클로 설치 ㄴ PT 트레이너 고용중 - 몽핏 챌린지 프로그램 개발 완료 - 머니메이커스 자산관리 시스템 개발중 - 개인 자산관리 시스템 개발 중 - 아이 장난감 재고 파악 - 아이 키즈카페 예약 시스템
...

Sheet 덕_2025
A1: 덕 2025년 연간계획
A3: 최종 목표
A4: - 내가 원하는 시간에 원하는 사람과 원하는 것을 원하는 곳에서 먹고 있다.
A5: - 100억 자산가
A6: - 배운 지식을 나누는 삶
A7: - 좋아하는 사람들과 월 1회 파티 모임
A8: - 근처에 사는 부모님과 분기별 여행
A9: - 친척들과 함께하는 가족 기업 및 사업
A12: 2025년 전략
A13: - 나는 매년 성장한
A14: - 부동산 저평가를 알고 투자할 곳을 알고 있다
A15: - 온라인 유통으로 억 매출을 달성하고 있다
A21: 1년 로드맵
A22: 분류 | B22: 2025년 목표 | C22: 상반기목표 | D22: 1분기 | E22: 1월 | F22: 2월 | G22: 3월 | H22: 2분기 | I22: 4월 | J22: 5월 | K22: 6월 | L22: 상반기 실적 | M22: 하반기목표 | N22: 3분기 | O22: 7월 | P22: 8월 | Q22: 9월 | R22: 4분기 | S22: 10월 | T22: 11월 | U22: 12월
A23: 부동산🎪 | B23: 전세4건 마무리 | C23: 1개 전세 재계약 | G23: - 구미 재계약 완료 | L23: 포항 전세 계약 | M23: 1개 전세 재계약
B24: 이익난거 매도하기 | C24: 수익률 정해서 매도 계획 추이 확인하기 | L24: 청주 매도 | M24: 수익률 정해서 매도 계획 추이 확인하기
A26: 강의📊 | B26: 부동산 강의 재수강 | C26: 강의 1개 | E26: - 바람의 색상 강의 | F26: - 분양권 강의 - 갭투자 강의 | G26: - 온라인 유통 강의 완료 | L26: - 손품왕 기술적 분석 무료특강 | M26: 강의 1개
B27: 부동산 책 보고 정리하기 | C27: 부동산 책 보고 정리 | M27: 부동산 책 보고 정리
B28: 부동산 대부들 블로그 보고 인사이트 얻기 | C28: 숙주나물, 부룡 등등 보고 블로그 작성 주 1회 | D28: 12회 | E28: 4회 | F28: 4회 | G28: 4회 | H28: 12회 | I28: 4회 | J28: 4회 | K28: 4회 | M28: 숙주나물, 부룡 등등 보고 블로그 작성 주 1회 | N28: 12회 | O28: 4회 | P28: 4회 | Q28: 4회 | R28: 12회 | S28: 4회 | T28: 4회 | U28: 4회
B29: 파이프라인 강의 | L29: - 쿠팡 강의 - 크림 강의
A31: 주식 | L31: - 주식 관련 책 + 추천 - 추천 마이너스.. - ETL 매수
A33: 파이프라인💰 | B33: 온라인 유통 사업 월 1천 매출 | C33: 월 1천 매출 | G33: - 다채널 3곳 가입 | L33: - 40만원 - 매일 소싱처 찾기 - 최소 100이상 구매 | M33: 월 2천 매출
B34: AI 연금 | L34: - 3만원 - 보류 중, 자동이니 할까?
A36: 독서📖 | B36: 최소 월 1권 이상 읽기 | C36: 12권 | D36: 6권 | E36: 2권 | F36: 2권 - 파서블 - 가성비 좋고 수익률 높은 부동산 투자 | G36: 2권 - 현명한투자자 - 비상식적 성공법칙 | H36: 6권 | I36: 2권 | J36: 2권 | K36: 2권 | L36: 8권 - 회복탄력성 - 결국 해내는 사람들 - ETF로 시작하라 - 결국 끝내 해내는 사람들 - 주린이 주식 투자 하기 - 나는 스무살의 나를 가장 존중한다 - 데일카네기의 자기개발론 | M36: 12권 | N36: 6권 | O36: 2권 | P36: 2권 | Q36: 2권 | R36: 6권 | S36: 2권 | T36: 2권 | U36: 2권
B37: 연 30권 목표 | C37: 15권 | D37: 7권 | E37: 2권 | F37: 3권 | G37: 2권 | H37: 8권 | I37: 3권 | J37: 2권 | K37: 3권 | M37: 15권 | N37: 7권 | O37: 2권 | P37: 3권 | Q37: 2권 | R37: 8권 | S37: 3권 | T37: 2권 | U37: 3권
B38: 12개의 이상 실행 목록 만들고 달성 | C38: 15개 실행 완료 | D38: 7개 | E38: 2개 | F38: 3개 | G38: 2개 | H38: 8개 | I38: 3개 | J38: 2개 | K38: 3개 | L38: 월별 목록 정리 후 실행 목표 | M38: 15개 실행 완료 | N38: 7개 | O38: 2개 | P38: 3개 | Q38: 2개 | R38: 8개 | S38: 3개 | T38: 2개 | U38: 3개
A40: 회사 | B40: 내게 도움되는 자격증 취득 | L40: - ADsP - DAsP - SPA
B41: 회사레버리지 | C41: 매달 최소 1개 이상 강의 듣기
A43: 건강🥋 | B43: 운동 주 4회 | L43: 잠시 보류 - 매일 스트레칭 중
B44: 근육량 35kg, 체지방율 12% | C44: 근육량 34kg 체지방율 14% | D44: 근육량 33kg 체지방율 15% | E44: 근육량 33kg 체지방율 15% | F44: 근육량 33kg 체지방율 15% | G44: 근육량 33kg 체지방율 15% - 주3회이상 운동 | H44: 근육량 34kg 체지방율 14% | I44: 근육량 34kg 체지방율 14% | J44: 근육량 34kg 체지방율 14% | K44: 근육량 34kg 체지방율 14% | M44: 근육량 35kg 체지방율 12%
